Workbook

Sheet Cover
B7: Deal Overview: | F7: Table of Contents:
B9: Company: | C9: ABC/SNS Health | F9: Outputs - Base
B10: Industry: | C10: Consumer Goods | F10: DCF Model - Base (1)
F11: DCF Model - Bull (2)
B12: Senario | C12: 1 | F12: DCF Model - Bear (3)
F13: WACC
B14: Implied Equity Value - GGM | C14: =CHOOSE($C$12,'DCF Model - Base (1)'!Q111,'DCF Model - Bull (2)'!Q111,'DCF Model - Bear (3)'!Q111) -> 19042.673 | F14: Comps
B15: Implied Equity Value - Multiples | C15: =CHOOSE($C$12,'DCF Model - Base (1)'!Q98,'DCF Model - Bull (2)'!Q98,'DCF Model - Bear (3)'!Q98) -> 25149.739 | F15: Assumption Breakdown
F16: Data Given (Recalcuated)
B17: Implied Upside - GGM | C17: =CHOOSE($C$12,'DCF Model - Base (1)'!Q113,'DCF Model - Bull (2)'!Q113,'DCF Model - Bear (3)'!Q113) -> 0.81358788 | F17: Data Given (Original)
B18: Implied Upside - Multiples | C18: =CHOOSE($C$12,'DCF Model - Base (1)'!Q100,'DCF Model - Bull (2)'!Q100,'DCF Model - Bear (3)'!Q100) -> 1.3952133
B20: Last Modified: | C20: 45855
B22: Authors: | F22: Legend:
B24: Name: | F24: xxx | G24: Hard Coded Figure
B25: Email: | F25: xxx | G25: Soft Coded Figure
B26: Phone Number: | F26: xxx | G26: Reference from Preceding Cell
F27: xxx | G27: Change in Formula/Odd Calculation
F28: xxx | G28: Reference from Other Worksheet

Sheet Ouputs - Base
B2: Discounted Cash Flow Output
B3: Company ABC/SNS Health
B4: All $ in CAD 000's unless otherwise stated
A6: x | B6: Discounted Cash Flow | H6: 2021 | I6: =H6+1 -> 2022 | J6: =I6+1 -> 2023 | K6: =J6+1 -> 2024 | L6: =K6+1 -> 2025 | M6: =L6+1 -> 2026 | N6: =M6+1 -> 2027 | O6: =N6+1 -> 2028 | P6: =O6+1 -> 2029 | Q6: =P6+1 -> 2030
B8: EBIT | J8: ='DCF Model - Base (1)'!J51 -> 3316.5682 | K8: ='DCF Model - Base (1)'!K51 -> 4462.5019 | L8: ='DCF Model - Base (1)'!L51 -> 5376.1724 | M8: ='DCF Model - Base (1)'!M51 -> 5490.4184 | N8: ='DCF Model - Base (1)'!N51 -> 5608.2919 | O8: ='DCF Model - Base (1)'!O51 -> 5727.8461 | P8: ='DCF Model - Base (1)'!P51 -> 5850.1354 | Q8: ='DCF Model - Base (1)'!Q51 -> 5975.2151
B9: (+) Depreciation & Amortization | J9: ='DCF Model - Base (1)'!J68 -> 638.82379 | K9: ='DCF Model - Base (1)'!K68 -> 670.48671 | L9: ='DCF Model - Base (1)'!L68 -> 715.72044 | M9: ='DCF Model - Base (1)'!M68 -> 730.03485 | N9: ='DCF Model - Base (1)'!N68 -> 744.63555 | O9: ='DCF Model - Base (1)'!O68 -> 759.52826 | P9: ='DCF Model - Base (1)'!P68 -> 774.71883 | Q9: ='DCF Model - Base (1)'!Q68 -> 790.2132
B10: EBITDA | J10: ='DCF Model - Base (1)'!J54 -> 3955.392 | K10: ='DCF Model - Base (1)'!K54 -> 5132.9886 | L10: ='DCF Model - Base (1)'!L54 -> 6091.8929 | M10: ='DCF Model - Base (1)'!M54 -> 6220.4532 | N10: ='DCF Model - Base (1)'!N54 -> 6352.9274 | O10: ='DCF Model - Base (1)'!O54 -> 6487.3744 | P10: ='DCF Model - Base (1)'!P54 -> 6624.8542 | Q10: ='DCF Model - Base (1)'!Q54 -> 6765.4283
B12: NOPAT | J12: ='DCF Model - Base (1)'!J60 -> 2437.6776 | K12: ='DCF Model - Base (1)'!K60 -> 3279.9389 | L12: ='DCF Model - Base (1)'!L60 -> 3951.4867 | M12: ='DCF Model - Base (1)'!M60 -> 4035.4575 | N12: ='DCF Model - Base (1)'!N60 -> 4122.0945 | O12: ='DCF Model - Base (1)'!O60 -> 4209.9669 | P12: ='DCF Model - Base (1)'!P60 -> 4299.8495 | Q12: ='DCF Model - Base (1)'!Q60 -> 4391.7831
B13: (+) Depreciation | J13: =J9 -> 638.82379 | K13: =K9 -> 670.48671 | L13: =L9 -> 715.72044 | M13: =M9 -> 730.03485 | N13: =N9 -> 744.63555 | O13: =O9 -> 759.52826 | P13: =P9 -> 774.71883 | Q13: =Q9 -> 790.2132
B14: (-) Capital Expenditures | J14: =-'DCF Model - Base (1)'!$F$9 -> -1000 | K14: =-'DCF Model - Base (1)'!$F$9 -> -1000 | L14: =-'DCF Model - Base (1)'!$F$9 -> -1000 | M14: =-'DCF Model - Base (1)'!$F$9 -> -1000 | N14: =-'DCF Model - Base (1)'!$F$9 -> -1000 | O14: =-'DCF Model - Base (1)'!$F$9 -> -1000 | P14: =-'DCF Model - Base (1)'!$F$9 -> -1000 | Q14: =-'DCF Model - Base (1)'!$F$9 -> -1000
B15: (-) Change in NWC | J15: =-'DCF Model - Base (1)'!$F$10 -> -100 | K15: =-'DCF Model - Base (1)'!$F$10 -> -100 | L15: =-'DCF Model - Base (1)'!$F$10 -> -100 | M15: =-'DCF Model - Base (1)'!$F$10 -> -100 | N15: =-'DCF Model - Base (1)'!$F$10 -> -100 | O15: =-'DCF Model - Base (1)'!$F$10 -> -100 | P15: =-'DCF Model - Base (1)'!$F$10 -> -100 | Q15: =-'DCF Model - Base (1)'!$F$10 -> -100
B16: Unlevered Free Cash Flow | H16: =H12+H13+H14+H15 -> 0 | I16: =I12+I13+I14+I15 -> 0 | J16: =SUM(J12:J15) -> 1976.5014 | K16: =SUM(K12:K15) -> 2850.4256 | L16: =SUM(L12:L15) -> 3567.2072 | M16: =SUM(M12:M15) -> 3665.4924 | N16: =SUM(N12:N15) -> 3766.7301 | O16: =SUM(O12:O15) -> 3869.4952 | P16: =SUM(P12:P15) -> 3974.5684 | Q16: =SUM(Q12:Q15) -> 4081.9963
B18: Date of Valuation | E18: ='DCF Model - Base (1)'!I9 -> 44781
B19: Date For Discounting Cash Flows | J19: ='DCF Model - Base (1)'!I11 -> 44926 | K19: =EOMONTH(J19,12) -> 45291 | L19: =EOMONTH(K19,12) -> 45657 | M19: =EOMONTH(L19,12) -> 46022 | N19: =EOMONTH(M19,12) -> 46387 | O19: =EOMONTH(N19,12) -> 46752 | P19: =EOMONTH(O19,12) -> 47118 | Q19: =EOMONTH(P19,12) -> 47483
B20: Period, Stub Adjusted | J20: =(J19-E18)/365 -> 0.39726027 | K20: =J20+1 -> 1.3972603 | L20: =K20+1 -> 2.3972603 | M20: =L20+1 -> 3.3972603 | N20: =M20+1 -> 4.3972603 | O20: =N20+1 -> 5.3972603 | P20: =O20+1 -> 6.3972603 | Q20: =P20+1 -> 7.3972603
B21: Discount Period, Stub and Mid-Year Adjusted | J21: =J20/2 -> 0.19863014 | K21: =K20-0.5 -> 0.89726027 | L21: =L20-0.5 -> 1.8972603 | M21: =M20-0.5 -> 2.8972603 | N21: =N20-0.5 -> 3.8972603 | O21: =O20-0.5 -> 4.8972603 | P21: =P20-0.5 -> 5.8972603 | Q21: =Q20-0.5 -> 6.8972603
B22: Discount Rate | J22: =WACC!$D$34 -> 0.20768485 | K22: =WACC!$D$34 -> 0.20768485 | L22: =WACC!$D$34 -> 0.20768485 | M22: =WACC!$D$34 -> 0.20768485 | N22: =WACC!$D$34 -> 0.20768485 | O22: =WACC!$D$34 -> 0.20768485 | P22: =WACC!$D$34 -> 0.20768485 | Q22: =WACC!$D$34 -> 0.20768485
A23: x | B23: Present Value of Unlevered Free Cash Flow | J23: =J16/(1+J22)^J21 -> 1903.7884 | K23: =K16/(1+K22)^K21 -> 2406.4452 | L23: =L16/(1+L22)^L21 -> 2493.6815 | M23: =M16/(1+M22)^M21 -> 2121.736 | N23: =N16/(1+N22)^N21 -> 1805.3854 | O23: =O16/(1+O22)^O21 -> 1535.699 | P23: =P16/(1+P22)^P21 -> 1306.1353 | Q23: =Q16/(1+Q22)^Q21 -> 1110.7522
B26: EV Calculation - Multiples Method | F26: EV Calculation - GGM | J26: Multiples Method
B27: WACC | D27: =WACC!$D$34 -> 0.20768485 | F27: WACC | H27: =WACC!$D$34 -> 0.20768485 | J27: Terminal Value % of TEV | L27: =D33/D35 -> 0.44901438
B28: Exit Multiple | D28: ='DCF Model - Base (1)'!C16 -> 6.5 | F28: Long Term Growth Rate | H28: 0.03 | J28: PV of UFCF % of TEV | L28: =D30/D35 -> 0.55098562
J29: Implied TV Exit EBITDA Multiple | L29: =D35/Q10 -> 3.939106
B30: PV of UFCF | D30: =SUM(H23:Q23) -> 14683.623 | F30: PV of UFCF | H30: =SUM(H23:Q23) -> 14683.623
B31: Final Year EBITDA | D31: =Q10 -> 6765.4283 | F31: 2024 x (1+g) | H31: =Q16*(1+H28) -> 4204.4562
B32: Terminal Value | D32: =D31*D28 -> 43975.284 | F32: Terminal Value | H32: =H31/(D27-H28) -> 23662.435
B33: PV of Terminal Value | D33: =D32/(1+D27)^Q21 -> 11966.116 | F33: PV of Terminal Value | H33: =H32/(1+H27)^Q20 -> 5859.0497
J34: Gordon Growth Method
B35: Enterprise Value | D35: =D33+D30 -> 26649.739 | F35: Enterprise Value | H35: =H33+H30 -> 20542.673 | J35: Terminal Value % of TEV | L35: =H33/H35 -> 0.2852136
B36: (-) Outstanding Debt | D36: =-'DCF Model - Base (1)'!F16 -> -1500 | F36: (-) Outstanding Debt | H36: =-'DCF Model - Base (1)'!$F$16 -> -1500 | J36: PV of UFCF % of TEV | L36: =H30/H35 -> 0.7147864
B37: (-) Minority Interest | D37: 0 | F37: (-) Minority Interest
B38: (+) Cash and Cash Equivalents | D38: 0 | F38: (+) Cash and Cash Equivalents
B40: Implied Equity Value | D40: =SUM(D35:D38) -> 25149.739 | F40: Implied Equity Value | H40: =SUM(H35:H38) -> 19042.673 | J40: Blended
B41: Current Equity Value | D41: ='DCF Model - Base (1)'!C12 -> 10500 | F41: Current Equity Value | H41: ='DCF Model - Base (1)'!C12 -> 10500 | J41: Terminal Value % of TEV | L41: =AVERAGE(L35,L27) -> 0.36711399
A42: x | B42: Implied Upside | D42: =D40/D41 - 1 -> 1.3952133 | F42: Implied Upside | H42: =H40/H41 - 1 -> 0.81358788 | J42: PV of UFCF % of TEV | L42: =AVERAGE(L36,L28) -> 0.63288601
A59: x

Sheet DCF Model - Base (1)
A2: x | B2: Discounted Cash Flow Model
B3: Company ABC/SNS Health
B4: All $ in CAD 000's unless otherwise stated
A6: x | B6: Assumptions
B8: Entry/Exit Assumptions | E8: Operating Assumptions | H8: Other Inputs
B9: Purchase Price | C9: 12000 | E9: CapEx | F9: 1000 | H9: Valuation Date | I9: 44781
B10: Purchase Multiple | C10: =C9/I54 -> 3.2425654 | E10: Change in NWC | F10: 100 | H10: Closing Date | I10: 45223
B11: Acquisition Costs | C11: 250 | E11: Tax Rate | F11: 0.265 | H11: Fiscal Year End | I11: 44926
B12: Equity Value | C12: =C9-F16 -> 10500 | E12: WACC | F12: =WACC!D34 -> 0.20768485
E13: D&A % revenue | F13: 0.039
B15: Exit Multiple Assumptions | E15: Deal Structure Assumptions
B16: Exit Multiple | C16: 6.5 | E16: Debt Assumed | F16: 1500
A18: x | B18: Income Statement | H18: 2021 | I18: =H18+1 -> 2022 | J18: =I18+1 -> 2023 | K18: =J18+1 -> 2024 | L18: =K18+1 -> 2025 | M18: =L18+1 -> 2026 | N18: =M18+1 -> 2027 | O18: =N18+1 -> 2028 | P18: =O18+1 -> 2029 | Q18: =P18+1 -> 2030 | S18: FY'21-22A | T18: FY'23-30E
B20: Revenue | H20: ='Original & Adjusted Data'!V12 -> 13563.457 | I20: ='Original & Adjusted Data'!W12 -> 15755.559 | J20: ='Original & Adjusted Data'!X12 -> 16380.097 | K20: ='Original & Adjusted Data'!Y12 -> 17191.967 | L20: ='Original & Adjusted Data'!Z12 -> 18351.806 | M20: ='Original & Adjusted Data'!AA12 -> 18718.842 | N20: ='Original & Adjusted Data'!AB12 -> 19093.219 | O20: ='Original & Adjusted Data'!AC12 -> 19475.084 | ... Q20: ='Original & Adjusted Data'!AE12 -> 20261.877 | S20: =+(I20/H20)^(1/(COLUMNS(H20:I20)-1))-1 -> 0.16161819 | T20: =+(Q20/J20)^(1/(COLUMNS(J20:Q20)-1))-1 -> 0.030848261
B21: % growth | I21: =I20/H20 - 1 -> 0.16161819 | J21: =J20/I20 - 1 -> 0.039639257 | K21: =K20/J20 - 1 -> 0.049564399 | L21: =L20/K20 - 1 -> 0.067464028 | M21: =M20/L20 - 1 -> 0.02 | N21: =N20/M20 - 1 -> 0.02 | O21: =O20/N20 - 1 -> 0.02 | P21: =P20/O20 - 1 -> 0.02 | Q21: =Q20/P20 - 1 -> 0.02
B23: Cost of Sales
B24: Purchases | H24: ='Original & Adjusted Data'!V16 -> 4886.8441 | I24: ='Original & Adjusted Data'!W16 -> 5278.8393 | J24: ='Original & Adjusted Data'!X16 -> 5386.671 | K24: ='Original & Adjusted Data'!Y16 -> 5052.221 | L24: ='Original & Adjusted Data'!Z16 -> 5153.2654 | M24: ='Original & Adjusted Data'!AA16 -> 5256.3307 | N24: ='Original & Adjusted Data'!AB16 -> 5361.4573 | O24: ='Original & Adjusted Data'!AC16 -> 5468.6864 | ... Q24: ='Original & Adjusted Data'!AE16 -> 5689.6214 | S24: =+(I24/H24)^(1/(COLUMNS(H24:I24)-1))-1 -> 0.080214384 | T24: =+(Q24/J24)^(1/(COLUMNS(J24:Q24)-1))-1 -> 0.0078472213
B25: % of revenue | H25: =H24/H20 -> 0.36029488 | I25: =I24/I20 -> 0.33504616 | J25: =J24/J20 -> 0.32885464 | K25: =K24/K20 -> 0.29387103 | L25: =L24/L20 -> 0.28080426 | M25: =M24/M20 -> 0.28080426 | N25: =N24/N20 -> 0.28080426 | O25: =O24/O20 -> 0.28080426 | ... Q25: =Q24/Q20 -> 0.28080426
B27: Sales Commission | H27: ='Original & Adjusted Data'!V17 -> 1877.8981 | I27: ='Original & Adjusted Data'!W17 -> 2622.0151 | J27: ='Original & Adjusted Data'!X17 -> 2916.193 | K27: ='Original & Adjusted Data'!Y17 -> 2916.193 | L27: ='Original & Adjusted Data'!Z17 -> 2974.5168 | M27: ='Original & Adjusted Data'!AA17 -> 3034.0072 | N27: ='Original & Adjusted Data'!AB17 -> 3094.6873 | O27: ='Original & Adjusted Data'!AC17 -> 3156.5811 | ... Q27: ='Original & Adjusted Data'!AE17 -> 3284.1069 | S27: =+(I27/H27)^(1/(COLUMNS(H27:I27)-1))-1 -> 0.39624998 | T27: =+(Q27/J27)^(1/(COLUMNS(J27:Q27)-1))-1 -> 0.017118552
B28: % of revenue | H28: =H27/H20 -> 0.13845276 | I28: =I27/I20 -> 0.16641842 | J28: =J27/J20 -> 0.1780327 | K28: =K27/K20 -> 0.16962532 | L28: =L27/L20 -> 0.16208306 | M28: =M27/M20 -> 0.16208306 | N28: =N27/N20 -> 0.16208306 | O28: =O27/O20 -> 0.16208306 | ... Q28: =Q27/Q20 -> 0.16208306
B30: Total Cost of Sales | H30: =H24+H27 -> 6764.7422 | I30: =I24+I27 -> 7900.8545 | J30: =J24+J27 -> 8302.8639 | K30: =K24+K27 -> 7968.4139 | L30: =L24+L27 -> 8127.7822 | M30: =M24+M27 -> 8290.3379 | N30: =N24+N27 -> 8456.1446 | O30: =O24+O27 -> 8625.2675 | ... Q30: =Q24+Q27 -> 8973.7283
B32: Gross Profit | H32: =H20-H30 -> 6798.7149 | I32: =I20-I30 -> 7854.7041 | J32: =J20-J30 -> 8077.2333 | K32: =K20-K30 -> 9223.553 | L32: =L20-L30 -> 10224.024 | M32: =M20-M30 -> 10428.505 | N32: =N20-N30 -> 10637.075 | O32: =O20-O30 -> 10849.816 | ... Q32: =Q20-Q30 -> 11288.149 | S32: =+(I32/H32)^(1/(COLUMNS(H32:I32)-1))-1 -> 0.15532188 | T32: =+(Q32/J32)^(1/(COLUMNS(J32:Q32)-1))-1 -> 0.048976425
B33: % margin | H33: =H32/H20 -> 0.50125236 | I33: =I32/I20 -> 0.49853543 | J33: =J32/J20 -> 0.49311266 | K33: =K32/K20 -> 0.53650365 | L33: =L32/L20 -> 0.55711268 | M33: =M32/M20 -> 0.55711268 | N33: =N32/N20 -> 0.55711268 | O33: =O32/O20 -> 0.55711268 | ... Q33: =Q32/Q20 -> 0.55711268
B35: Operating Expenses
B36: G&A | H36: ='Original & Adjusted Data'!V24 -> 3732.3638 | I36: ='Original & Adjusted Data'!W24 -> 4224.707 | J36: ='Original & Adjusted Data'!X24 -> 4056.7653 | K36: ='Original & Adjusted Data'!Y24 -> 4200.9513 | L36: ='Original & Adjusted Data'!Z24 -> 4279.3504 | M36: ='Original & Adjusted Data'!AA24 -> 4361.0574 | N36: ='Original & Adjusted Data'!AB24 -> 4443.0985 | O36: ='Original & Adjusted Data'!AC24 -> 4527.5005 | ... Q36: ='Original & Adjusted Data'!AE24 -> 4700.4963 | S36: =+(I36/H36)^(1/(COLUMNS(H36:I36)-1))-1 -> 0.1319119 | T36: =+(Q36/J36)^(1/(COLUMNS(J36:Q36)-1))-1 -> 0.021263216
B37: % of revenue | H37: =H36/H20 -> 0.27517791 | I37: =I36/I20 -> 0.26814073 | J37: =J36/J20 -> 0.2476643 | K37: =K36/K20 -> 0.24435548 | L37: =L36/L20 -> 0.23318415 | M37: =M36/M20 -> 0.23297687 | N37: =N36/N20 -> 0.23270557 | O37: =O36/O20 -> 0.23247656 | ... Q37: =Q36/Q20 -> 0.23198721
B39: Facility/Office Rent | H39: ='Original & Adjusted Data'!V25 -> 233.78641 | I39: ='Original & Adjusted Data'!W25 -> 231.49663 | J39: ='Original & Adjusted Data'!X25 -> 273.1192 | K39: ='Original & Adjusted Data'!Y25 -> 273.1192 | L39: ='Original & Adjusted Data'!Z25 -> 277.21599 | M39: ='Original & Adjusted Data'!AA25 -> 281.37423 | N39: ='Original & Adjusted Data'!AB25 -> 285.59484 | O39: ='Original & Adjusted Data'!AC25 -> 289.87876 | ... Q39: ='Original & Adjusted Data'!AE25 -> 298.64035 | S39: =+(I39/H39)^(1/(COLUMNS(H39:I39)-1))-1 -> -0.0097943247 | T39: =+(Q39/J39)^(1/(COLUMNS(J39:Q39)-1))-1 -> 0.012843445
B40: % of revenue | H40: =H39/H20 -> 0.017236491 | I40: =I39/I20 -> 0.014693013 | J40: =J39/J20 -> 0.016673845 | K40: =K39/K20 -> 0.015886443 | L40: =L39/L20 -> 0.015105651 | M40: =M39/M20 -> 0.015031604 | N40: =N39/N20 -> 0.01495792 | O40: =O39/O20 -> 0.014884597 | ... Q40: =Q39/Q20 -> 0.014739027
B42: Bad Debt Expense | H42: ='Original & Adjusted Data'!V26 -> 139.57787 | I42: ='Original & Adjusted Data'!W26 -> 21.18842 | J42: ='Original & Adjusted Data'!X26 -> 110.17088 | K42: ='Original & Adjusted Data'!Y26 -> 110.17056 | L42: ='Original & Adjusted Data'!Z26 -> 111.82312 | M42: ='Original & Adjusted Data'!AA26 -> 113.50047 | N42: ='Original & Adjusted Data'!AB26 -> 115.20297 | O42: ='Original & Adjusted Data'!AC26 -> 116.93102 | ... Q42: ='Original & Adjusted Data'!AE26 -> 120.46526 | S42: =+(I42/H42)^(1/(COLUMNS(H42:I42)-1))-1 -> -0.84819642 | T42: =+(Q42/J42)^(1/(COLUMNS(J42:Q42)-1))-1 -> 0.012843025
B43: % of revenue | H43: =H42/H20 -> 0.01029073 | I43: =I42/I20 -> 0.0013448219 | J43: =J42/J20 -> 0.006725899 | K43: =K42/K20 -> 0.006408258 | L43: =L42/L20 -> 0.0060933031 | M43: =M42/M20 -> 0.006063434 | N43: =N42/N20 -> 0.0060337113 | O43: =O42/O20 -> 0.0060041343 | ... Q43: =Q42/Q20 -> 0.0059454145
B45: Other | H45: ='Original & Adjusted Data'!V27 -> 202.16042 | I45: ='Original & Adjusted Data'!W27 -> 291.00544 | J45: ='Original & Adjusted Data'!X27 -> 320.60966 | K45: ='Original & Adjusted Data'!Y27 -> 176.81 | L45: ='Original & Adjusted Data'!Z27 -> 179.46215 | M45: ='Original & Adjusted Data'!AA27 -> 182.15408 | N45: ='Original & Adjusted Data'!AB27 -> 184.88639 | O45: ='Original & Adjusted Data'!AC27 -> 187.65969 | ... Q45: ='Original & Adjusted Data'!AE27 -> 193.3317 | S45: =+(I45/H45)^(1/(COLUMNS(H45:I45)-1))-1 -> 0.43947785 | T45: =+(Q45/J45)^(1/(COLUMNS(J45:Q45)-1))-1 -> -0.06971061
B46: % of revenue | H46: =H45/H20 -> 0.014904785 | I46: =I45/I20 -> 0.018470017 | J46: =J45/J20 -> 0.019573123 | K46: =K45/K20 -> 0.010284454 | L46: =L45/L20 -> 0.0097789911 | M46: =M45/M20 -> 0.0097310549 | N46: =N45/N20 -> 0.0096833536 | O46: =O45/O20 -> 0.0096358862 | ... Q46: =Q45/Q20 -> 0.0095416483
B48: Total Operating Expenses | H48: =-(H36+H39+H42+H45) -> -4307.8885 | I48: =-(I36+I39+I42+I45) -> -4768.3975 | J48: =-(J36+J39+J42+J45) -> -4760.6651 | K48: =-(K36+K39+K42+K45) -> -4761.0511 | L48: =-(L36+L39+L42+L45) -> -4847.8516 | M48: =-(M36+M39+M42+M45) -> -4938.0861 | N48: =-(N36+N39+N42+N45) -> -5028.7827 | O48: =-(O36+O39+O42+O45) -> -5121.97 | ... Q48: =-(Q36+Q39+Q42+Q45) -> -5312.9336 | S48: =+(I48/H48)^(1/(COLUMNS(H48:I48)-1))-1 -> 0.10689901 | T48: =+(Q48/J48)^(1/(COLUMNS(J48:Q48)-1))-1 -> 0.015803108
B49: % of revenue | H49: =-H48/H20 -> 0.31760991 | I49: =-I48/I20 -> 0.30264858 | J49: =-J48/J20 -> 0.29063717 | K49: =-K48/K20 -> 0.27693464 | L49: =-L48/L20 -> 0.2641621 | M49: =-M48/M20 -> 0.26380297 | N49: =-N48/N20 -> 0.26338056 | O49: =-O48/O20 -> 0.26300118 | ... Q49: =-Q48/Q20 -> 0.2622133
B51: EBIT | H51: =H32+H48 -> 2490.8265 | I51: =I32+I48 -> 3086.3067 | J51: =J32+J48 -> 3316.5682 | K51: =K32+K48 -> 4462.5019 | L51: =L32+L48 -> 5376.1724 | M51: =M32+M48 -> 5490.4184 | N51: =N32+N48 -> 5608.2919 | O51: =O32+O48 -> 5727.8461 | ... Q51: =Q32+Q48 -> 5975.2151 | S51: =+(I51/H51)^(1/(COLUMNS(H51:I51)-1))-1 -> 0.23906931 | T51: =+(Q51/J51)^(1/(COLUMNS(J51:Q51)-1))-1 -> 0.087736032
B52: % margin | H52: =H51/H20 -> 0.18364245 | I52: =I51/I20 -> 0.19588684 | J52: =J51/J20 -> 0.20247549 | K52: =K51/K20 -> 0.25956901 | L52: =L51/L20 -> 0.29295059 | M52: =M51/M20 -> 0.29330972 | N52: =N51/N20 -> 0.29373213 | O52: =O51/O20 -> 0.2941115 | ... Q52: =Q51/Q20 -> 0.29489938
B54: EBITDA | H54: =H51+H68 -> 3033.3648 | I54: =I51+I68 -> 3700.7734 | J54: =J51+J68 -> 3955.392 | K54: =K51+K68 -> 5132.9886 | L54: =L51+L68 -> 6091.8929 | M54: =M51+M68 -> 6220.4532 | N54: =N51+N68 -> 6352.9274 | O54: =O51+O68 -> 6487.3744 | ... Q54: =Q51+Q68 -> 6765.4283 | S54: =+(I54/H54)^(1/(COLUMNS(H54:I54)-1))-1 -> 0.22002255 | T54: =+(Q54/J54)^(1/(COLUMNS(J54:Q54)-1))-1 -> 0.079694335
B55: % margin | H55: =H54/H20 -> 0.22364245 | I55: =I54/I20 -> 0.23488684 | J55: =J54/J20 -> 0.24147549 | K55: =K54/K20 -> 0.29856901 | L55: =L54/L20 -> 0.33195059 | M55: =M54/M20 -> 0.33230972 | N55: =N54/N20 -> 0.33273213 | O55: =O54/O20 -> 0.3331115 | ... Q55: =Q54/Q20 -> 0.33389938
B57: Taxes | H57: =-H51*H58 -> -660.06902 | I57: =-I51*I58 -> -817.87126 | J57: =-J51*J58 -> -878.89058 | K57: =-K51*K58 -> -1182.563 | L57: =-L51*L58 -> -1424.6857 | M57: =-M51*M58 -> -1454.9609 | N57: =-N51*N58 -> -1486.1974 | O57: =-O51*O58 -> -1517.8792 | ... Q57: =-Q51*Q58 -> -1583.432
B58: % tax rate | H58: =$F$11 -> 0.265 | I58: =$F$11 -> 0.265 | J58: =$F$11 -> 0.265 | K58: =$F$11 -> 0.265 | L58: =$F$11 -> 0.265 | M58: =$F$11 -> 0.265 | N58: =$F$11 -> 0.265 | O58: =$F$11 -> 0.265 | ... Q58: =$F$11 -> 0.265
...

Sheet DCF Model - Bull (2)
A2: x | B2: Discounted Cash Flow Model
B3: Company ABC/SNS Health
B4: All $ in CAD 000's unless otherwise stated
A6: x | B6: Assumptions
B8: Entry/Exit Assumptions | E8: Operating Assumptions | H8: Other Inputs
B9: Purchase Price | C9: 12000 | E9: CapEx | F9: 1000 | H9: Valuation Date | I9: 44781
B10: Purchase Multiple | C10: =C9/I54 -> 3.2425654 | E10: Change in NWC | F10: 100 | H10: Closing Date | I10: 45223
B11: Acquisition Costs | C11: 250 | E11: Tax Rate | F11: 0.265 | H11: Fiscal Year End | I11: 44926
B12: Equity Value | C12: =C9-F16 -> 10500 | E12: WACC | F12: ='DCF Model - Base (1)'!F12-0.01 -> 0.19768485
E13: D&A % revenue | F13: 0.039
B15: Exit Multiple Assumptions | E15: Deal Structure Assumptions
B16: Exit Multiple | C16: 6.5 | E16: Debt Assumed | F16: 1500
A18: x | B18: Income Statement | H18: 2021 | I18: =H18+1 -> 2022 | J18: =I18+1 -> 2023 | K18: =J18+1 -> 2024 | L18: =K18+1 -> 2025 | M18: =L18+1 -> 2026 | N18: =M18+1 -> 2027 | O18: =N18+1 -> 2028 | P18: =O18+1 -> 2029 | Q18: =P18+1 -> 2030 | S18: FY'21-22A | T18: FY'23-30E
B20: Revenue | H20: ='Original & Adjusted Data'!V12 -> 13563.457 | I20: ='Original & Adjusted Data'!W12 -> 15755.559 | J20: ='Original & Adjusted Data'!X12 -> 16380.097 | K20: ='Original & Adjusted Data'!Y12 -> 17191.967 | L20: ='Original & Adjusted Data'!Z12 -> 18351.806 | M20: ='Original & Adjusted Data'!AA12 -> 18718.842 | N20: ='Original & Adjusted Data'!AB12 -> 19093.219 | O20: ='Original & Adjusted Data'!AC12 -> 19475.084 | ... Q20: ='Original & Adjusted Data'!AE12 -> 20261.877 | S20: =+(I20/H20)^(1/(COLUMNS(H20:I20)-1))-1 -> 0.16161819 | T20: =+(Q20/J20)^(1/(COLUMNS(J20:Q20)-1))-1 -> 0.030848261
B21: % growth | I21: =I20/H20 - 1 -> 0.16161819 | J21: =J20/I20 - 1 -> 0.039639257 | K21: =K20/J20 - 1 -> 0.049564399 | L21: =L20/K20 - 1 -> 0.067464028 | M21: =M20/L20 - 1 -> 0.02 | N21: =N20/M20 - 1 -> 0.02 | O21: =O20/N20 - 1 -> 0.02 | P21: =P20/O20 - 1 -> 0.02 | Q21: =Q20/P20 - 1 -> 0.02
B23: Cost of Sales
B24: Purchases | H24: ='Original & Adjusted Data'!V16 -> 4886.8441 | I24: ='Original & Adjusted Data'!W16 -> 5278.8393 | J24: ='Original & Adjusted Data'!X16 -> 5386.671 | K24: ='Original & Adjusted Data'!Y16 -> 5052.221 | L24: ='Original & Adjusted Data'!Z16 -> 5153.2654 | M24: ='Original & Adjusted Data'!AA16 -> 5256.3307 | N24: ='Original & Adjusted Data'!AB16 -> 5361.4573 | O24: ='Original & Adjusted Data'!AC16 -> 5468.6864 | ... Q24: ='Original & Adjusted Data'!AE16 -> 5689.6214 | S24: =+(I24/H24)^(1/(COLUMNS(H24:I24)-1))-1 -> 0.080214384 | T24: =+(Q24/J24)^(1/(COLUMNS(J24:Q24)-1))-1 -> 0.0078472213
B25: % of revenue | H25: =H24/H20 -> 0.36029488 | I25: =I24/I20 -> 0.33504616 | J25: =J24/J20 -> 0.32885464 | K25: =K24/K20 -> 0.29387103 | L25: =L24/L20 -> 0.28080426 | M25: =M24/M20 -> 0.28080426 | N25: =N24/N20 -> 0.28080426 | O25: =O24/O20 -> 0.28080426 | ... Q25: =Q24/Q20 -> 0.28080426
B27: Sales Commission | H27: ='Original & Adjusted Data'!V17 -> 1877.8981 | I27: ='Original & Adjusted Data'!W17 -> 2622.0151 | J27: ='Original & Adjusted Data'!X17 -> 2916.193 | K27: ='Original & Adjusted Data'!Y17 -> 2916.193 | L27: ='Original & Adjusted Data'!Z17 -> 2974.5168 | M27: ='Original & Adjusted Data'!AA17 -> 3034.0072 | N27: ='Original & Adjusted Data'!AB17 -> 3094.6873 | O27: ='Original & Adjusted Data'!AC17 -> 3156.5811 | ... Q27: ='Original & Adjusted Data'!AE17 -> 3284.1069 | S27: =+(I27/H27)^(1/(COLUMNS(H27:I27)-1))-1 -> 0.39624998 | T27: =+(Q27/J27)^(1/(COLUMNS(J27:Q27)-1))-1 -> 0.017118552
B28: % of revenue | H28: =H27/H20 -> 0.13845276 | I28: =I27/I20 -> 0.16641842 | J28: =J27/J20 -> 0.1780327 | K28: =K27/K20 -> 0.16962532 | L28: =L27/L20 -> 0.16208306 | M28: =M27/M20 -> 0.16208306 | N28: =N27/N20 -> 0.16208306 | O28: =O27/O20 -> 0.16208306 | ... Q28: =Q27/Q20 -> 0.16208306
B30: Total Cost of Sales | H30: =H24+H27 -> 6764.7422 | I30: =I24+I27 -> 7900.8545 | J30: =J24+J27 -> 8302.8639 | K30: =K24+K27 -> 7968.4139 | L30: =L24+L27 -> 8127.7822 | M30: =M24+M27 -> 8290.3379 | N30: =N24+N27 -> 8456.1446 | O30: =O24+O27 -> 8625.2675 | ... Q30: =Q24+Q27 -> 8973.7283
B32: Gross Profit | H32: =H20-H30 -> 6798.7149 | I32: =I20-I30 -> 7854.7041 | J32: =J20-J30 -> 8077.2333 | K32: =K20-K30 -> 9223.553 | L32: =L20-L30 -> 10224.024 | M32: =M20-M30 -> 10428.505 | N32: =N20-N30 -> 10637.075 | O32: =O20-O30 -> 10849.816 | ... Q32: =Q20-Q30 -> 11288.149 | S32: =+(I32/H32)^(1/(COLUMNS(H32:I32)-1))-1 -> 0.15532188 | T32: =+(Q32/J32)^(1/(COLUMNS(J32:Q32)-1))-1 -> 0.048976425
B33: % margin | H33: =H32/H20 -> 0.50125236 | I33: =I32/I20 -> 0.49853543 | J33: =J32/J20 -> 0.49311266 | K33: =K32/K20 -> 0.53650365 | L33: =L32/L20 -> 0.55711268 | M33: =M32/M20 -> 0.55711268 | N33: =N32/N20 -> 0.55711268 | O33: =O32/O20 -> 0.55711268 | ... Q33: =Q32/Q20 -> 0.55711268
B35: Operating Expenses
B36: G&A | H36: ='Original & Adjusted Data'!V24 -> 3732.3638 | I36: ='Original & Adjusted Data'!W24 -> 4224.707 | J36: ='Original & Adjusted Data'!X24 -> 4056.7653 | K36: ='Original & Adjusted Data'!Y24 -> 4200.9513 | L36: ='Original & Adjusted Data'!Z24 -> 4279.3504 | M36: ='Original & Adjusted Data'!AA24 -> 4361.0574 | N36: ='Original & Adjusted Data'!AB24 -> 4443.0985 | O36: ='Original & Adjusted Data'!AC24 -> 4527.5005 | ... Q36: ='Original & Adjusted Data'!AE24 -> 4700.4963 | S36: =+(I36/H36)^(1/(COLUMNS(H36:I36)-1))-1 -> 0.1319119 | T36: =+(Q36/J36)^(1/(COLUMNS(J36:Q36)-1))-1 -> 0.021263216
B37: % of revenue | H37: =H36/H20 -> 0.27517791 | I37: =I36/I20 -> 0.26814073 | J37: =J36/J20 -> 0.2476643 | K37: =K36/K20 -> 0.24435548 | L37: =L36/L20 -> 0.23318415 | M37: =M36/M20 -> 0.23297687 | N37: =N36/N20 -> 0.23270557 | O37: =O36/O20 -> 0.23247656 | ... Q37: =Q36/Q20 -> 0.23198721
B39: Facility/Office Rent | H39: ='Original & Adjusted Data'!V25 -> 233.78641 | I39: ='Original & Adjusted Data'!W25 -> 231.49663 | J39: ='Original & Adjusted Data'!X25 -> 273.1192 | K39: ='Original & Adjusted Data'!Y25 -> 273.1192 | L39: ='Original & Adjusted Data'!Z25 -> 277.21599 | M39: ='Original & Adjusted Data'!AA25 -> 281.37423 | N39: ='Original & Adjusted Data'!AB25 -> 285.59484 | O39: ='Original & Adjusted Data'!AC25 -> 289.87876 | ... Q39: ='Original & Adjusted Data'!AE25 -> 298.64035 | S39: =+(I39/H39)^(1/(COLUMNS(H39:I39)-1))-1 -> -0.0097943247 | T39: =+(Q39/J39)^(1/(COLUMNS(J39:Q39)-1))-1 -> 0.012843445
B40: % of revenue | H40: =H39/H20 -> 0.017236491 | I40: =I39/I20 -> 0.014693013 | J40: =J39/J20 -> 0.016673845 | K40: =K39/K20 -> 0.015886443 | L40: =L39/L20 -> 0.015105651 | M40: =M39/M20 -> 0.015031604 | N40: =N39/N20 -> 0.01495792 | O40: =O39/O20 -> 0.014884597 | ... Q40: =Q39/Q20 -> 0.014739027
B42: Bad Debt Expense | H42: ='Original & Adjusted Data'!V26 -> 139.57787 | I42: ='Original & Adjusted Data'!W26 -> 21.18842 | J42: ='Original & Adjusted Data'!X26 -> 110.17088 | K42: ='Original & Adjusted Data'!Y26 -> 110.17056 | L42: ='Original & Adjusted Data'!Z26 -> 111.82312 | M42: ='Original & Adjusted Data'!AA26 -> 113.50047 | N42: ='Original & Adjusted Data'!AB26 -> 115.20297 | O42: ='Original & Adjusted Data'!AC26 -> 116.93102 | ... Q42: ='Original & Adjusted Data'!AE26 -> 120.46526 | S42: =+(I42/H42)^(1/(COLUMNS(H42:I42)-1))-1 -> -0.84819642 | T42: =+(Q42/J42)^(1/(COLUMNS(J42:Q42)-1))-1 -> 0.012843025
B43: % of revenue | H43: =H42/H20 -> 0.01029073 | I43: =I42/I20 -> 0.0013448219 | J43: =J42/J20 -> 0.006725899 | K43: =K42/K20 -> 0.006408258 | L43: =L42/L20 -> 0.0060933031 | M43: =M42/M20 -> 0.006063434 | N43: =N42/N20 -> 0.0060337113 | O43: =O42/O20 -> 0.0060041343 | ... Q43: =Q42/Q20 -> 0.0059454145
B45: Other | H45: ='Original & Adjusted Data'!V27 -> 202.16042 | I45: ='Original & Adjusted Data'!W27 -> 291.00544 | J45: ='Original & Adjusted Data'!X27 -> 320.60966 | K45: ='Original & Adjusted Data'!Y27 -> 176.81 | L45: ='Original & Adjusted Data'!Z27 -> 179.46215 | M45: ='Original & Adjusted Data'!AA27 -> 182.15408 | N45: ='Original & Adjusted Data'!AB27 -> 184.88639 | O45: ='Original & Adjusted Data'!AC27 -> 187.65969 | ... Q45: ='Original & Adjusted Data'!AE27 -> 193.3317 | S45: =+(I45/H45)^(1/(COLUMNS(H45:I45)-1))-1 -> 0.43947785 | T45: =+(Q45/J45)^(1/(COLUMNS(J45:Q45)-1))-1 -> -0.06971061
B46: % of revenue | H46: =H45/H20 -> 0.014904785 | I46: =I45/I20 -> 0.018470017 | J46: =J45/J20 -> 0.019573123 | K46: =K45/K20 -> 0.010284454 | L46: =L45/L20 -> 0.0097789911 | M46: =M45/M20 -> 0.0097310549 | N46: =N45/N20 -> 0.0096833536 | O46: =O45/O20 -> 0.0096358862 | ... Q46: =Q45/Q20 -> 0.0095416483
B48: Total Operating Expenses | H48: =-(H36+H39+H42+H45) -> -4307.8885 | I48: =-(I36+I39+I42+I45) -> -4768.3975 | J48: =-(J36+J39+J42+J45) -> -4760.6651 | K48: =-(K36+K39+K42+K45) -> -4761.0511 | L48: =-(L36+L39+L42+L45) -> -4847.8516 | M48: =-(M36+M39+M42+M45) -> -4938.0861 | N48: =-(N36+N39+N42+N45) -> -5028.7827 | O48: =-(O36+O39+O42+O45) -> -5121.97 | ... Q48: =-(Q36+Q39+Q42+Q45) -> -5312.9336 | S48: =+(I48/H48)^(1/(COLUMNS(H48:I48)-1))-1 -> 0.10689901 | T48: =+(Q48/J48)^(1/(COLUMNS(J48:Q48)-1))-1 -> 0.015803108
B49: % of revenue | H49: =-H48/H20 -> 0.31760991 | I49: =-I48/I20 -> 0.30264858 | J49: =-J48/J20 -> 0.29063717 | K49: =-K48/K20 -> 0.27693464 | L49: =-L48/L20 -> 0.2641621 | M49: =-M48/M20 -> 0.26380297 | N49: =-N48/N20 -> 0.26338056 | O49: =-O48/O20 -> 0.26300118 | ... Q49: =-Q48/Q20 -> 0.2622133
B51: EBIT | H51: =H32+H48 -> 2490.8265 | I51: =I32+I48 -> 3086.3067 | J51: =J32+J48 -> 3316.5682 | K51: =K32+K48 -> 4462.5019 | L51: =L32+L48 -> 5376.1724 | M51: =M32+M48 -> 5490.4184 | N51: =N32+N48 -> 5608.2919 | O51: =O32+O48 -> 5727.8461 | ... Q51: =Q32+Q48 -> 5975.2151 | S51: =+(I51/H51)^(1/(COLUMNS(H51:I51)-1))-1 -> 0.23906931 | T51: =+(Q51/J51)^(1/(COLUMNS(J51:Q51)-1))-1 -> 0.087736032
B52: % margin | H52: =H51/H20 -> 0.18364245 | I52: =I51/I20 -> 0.19588684 | J52: =J51/J20 -> 0.20247549 | K52: =K51/K20 -> 0.25956901 | L52: =L51/L20 -> 0.29295059 | M52: =M51/M20 -> 0.29330972 | N52: =N51/N20 -> 0.29373213 | O52: =O51/O20 -> 0.2941115 | ... Q52: =Q51/Q20 -> 0.29489938
B54: EBITDA | H54: =H51+H68 -> 3033.3648 | I54: =I51+I68 -> 3700.7734 | J54: =J51+J68 -> 3955.392 | K54: =K51+K68 -> 5132.9886 | L54: =L51+L68 -> 6091.8929 | M54: =M51+M68 -> 6220.4532 | N54: =N51+N68 -> 6352.9274 | O54: =O51+O68 -> 6487.3744 | ... Q54: =Q51+Q68 -> 6765.4283 | S54: =+(I54/H54)^(1/(COLUMNS(H54:I54)-1))-1 -> 0.22002255 | T54: =+(Q54/J54)^(1/(COLUMNS(J54:Q54)-1))-1 -> 0.079694335
B55: % margin | H55: =H54/H20 -> 0.22364245 | I55: =I54/I20 -> 0.23488684 | J55: =J54/J20 -> 0.24147549 | K55: =K54/K20 -> 0.29856901 | L55: =L54/L20 -> 0.33195059 | M55: =M54/M20 -> 0.33230972 | N55: =N54/N20 -> 0.33273213 | O55: =O54/O20 -> 0.3331115 | ... Q55: =Q54/Q20 -> 0.33389938
B57: Taxes | H57: =-H51*H58 -> -660.06902 | I57: =-I51*I58 -> -817.87126 | J57: =-J51*J58 -> -878.89058 | K57: =-K51*K58 -> -1182.563 | L57: =-L51*L58 -> -1424.6857 | M57: =-M51*M58 -> -1454.9609 | N57: =-N51*N58 -> -1486.1974 | O57: =-O51*O58 -> -1517.8792 | ... Q57: =-Q51*Q58 -> -1583.432
B58: % tax rate | H58: =$F$11 -> 0.265 | I58: =$F$11 -> 0.265 | J58: =$F$11 -> 0.265 | K58: =$F$11 -> 0.265 | L58: =$F$11 -> 0.265 | M58: =$F$11 -> 0.265 | N58: =$F$11 -> 0.265 | O58: =$F$11 -> 0.265 | ... Q58: =$F$11 -> 0.265
...

Sheet DCF Model - Bear (3)
A2: x | B2: Discounted Cash Flow Model
B3: Company ABC/SNS Health
B4: All $ in CAD 000's unless otherwise stated
A6: x | B6: Assumptions
B8: Entry/Exit Assumptions | E8: Operating Assumptions | H8: Other Inputs
B9: Purchase Price | C9: 12000 | E9: CapEx | F9: 1000 | H9: Valuation Date | I9: 44781
B10: Purchase Multiple | C10: =C9/I54 -> 3.2425654 | E10: Change in NWC | F10: 200 | H10: Closing Date | I10: 45223
B11: Acquisition Costs | C11: 250 | E11: Tax Rate | F11: 0.265 | H11: Fiscal Year End | I11: 44926
B12: Equity Value | C12: =C9-F16 -> 10500 | E12: WACC | F12: ='DCF Model - Base (1)'!F12+0.01 -> 0.21768485
E13: D&A % revenue | F13: 0.039
B15: Exit Multiple Assumptions | E15: Deal Structure Assumptions
B16: Exit Multiple | C16: 6.5 | E16: Debt Assumed | F16: 1500
A18: x | B18: Income Statement | H18: 2021 | I18: =H18+1 -> 2022 | J18: =I18+1 -> 2023 | K18: =J18+1 -> 2024 | L18: =K18+1 -> 2025 | M18: =L18+1 -> 2026 | N18: =M18+1 -> 2027 | O18: =N18+1 -> 2028 | P18: =O18+1 -> 2029 | Q18: =P18+1 -> 2030 | S18: FY'21-22A | T18: FY'23-30E
B20: Revenue | H20: ='Original & Adjusted Data'!V12 -> 13563.457 | I20: ='Original & Adjusted Data'!W12 -> 15755.559 | J20: ='Original & Adjusted Data'!X12 -> 16380.097 | K20: ='Original & Adjusted Data'!Y12 -> 17191.967 | L20: ='Original & Adjusted Data'!Z12 -> 18351.806 | M20: ='Original & Adjusted Data'!AA12 -> 18718.842 | N20: ='Original & Adjusted Data'!AB12 -> 19093.219 | O20: ='Original & Adjusted Data'!AC12 -> 19475.084 | ... Q20: ='Original & Adjusted Data'!AE12 -> 20261.877 | S20: =+(I20/H20)^(1/(COLUMNS(H20:I20)-1))-1 -> 0.16161819 | T20: =+(Q20/J20)^(1/(COLUMNS(J20:Q20)-1))-1 -> 0.030848261
B21: % growth | I21: =I20/H20 - 1 -> 0.16161819 | J21: =J20/I20 - 1 -> 0.039639257 | K21: =K20/J20 - 1 -> 0.049564399 | L21: =L20/K20 - 1 -> 0.067464028 | M21: =M20/L20 - 1 -> 0.02 | N21: =N20/M20 - 1 -> 0.02 | O21: =O20/N20 - 1 -> 0.02 | P21: =P20/O20 - 1 -> 0.02 | Q21: =Q20/P20 - 1 -> 0.02
B23: Cost of Sales
B24: Purchases | H24: ='Original & Adjusted Data'!V16 -> 4886.8441 | I24: ='Original & Adjusted Data'!W16 -> 5278.8393 | J24: ='Original & Adjusted Data'!X16 -> 5386.671 | K24: ='Original & Adjusted Data'!Y16 -> 5052.221 | L24: ='Original & Adjusted Data'!Z16 -> 5153.2654 | M24: ='Original & Adjusted Data'!AA16 -> 5256.3307 | N24: ='Original & Adjusted Data'!AB16 -> 5361.4573 | O24: ='Original & Adjusted Data'!AC16 -> 5468.6864 | ... Q24: ='Original & Adjusted Data'!AE16 -> 5689.6214 | S24: =+(I24/H24)^(1/(COLUMNS(H24:I24)-1))-1 -> 0.080214384 | T24: =+(Q24/J24)^(1/(COLUMNS(J24:Q24)-1))-1 -> 0.0078472213
B25: % of revenue | H25: =H24/H20 -> 0.36029488 | I25: =I24/I20 -> 0.33504616 | J25: =J24/J20 -> 0.32885464 | K25: =K24/K20 -> 0.29387103 | L25: =L24/L20 -> 0.28080426 | M25: =M24/M20 -> 0.28080426 | N25: =N24/N20 -> 0.28080426 | O25: =O24/O20 -> 0.28080426 | ... Q25: =Q24/Q20 -> 0.28080426
B27: Sales Commission | H27: ='Original & Adjusted Data'!V17 -> 1877.8981 | I27: ='Original & Adjusted Data'!W17 -> 2622.0151 | J27: ='Original & Adjusted Data'!X17 -> 2916.193 | K27: ='Original & Adjusted Data'!Y17 -> 2916.193 | L27: ='Original & Adjusted Data'!Z17 -> 2974.5168 | M27: ='Original & Adjusted Data'!AA17 -> 3034.0072 | N27: ='Original & Adjusted Data'!AB17 -> 3094.6873 | O27: ='Original & Adjusted Data'!AC17 -> 3156.5811 | ... Q27: ='Original & Adjusted Data'!AE17 -> 3284.1069 | S27: =+(I27/H27)^(1/(COLUMNS(H27:I27)-1))-1 -> 0.39624998 | T27: =+(Q27/J27)^(1/(COLUMNS(J27:Q27)-1))-1 -> 0.017118552
B28: % of revenue | H28: =H27/H20 -> 0.13845276 | I28: =I27/I20 -> 0.16641842 | J28: =J27/J20 -> 0.1780327 | K28: =K27/K20 -> 0.16962532 | L28: =L27/L20 -> 0.16208306 | M28: =M27/M20 -> 0.16208306 | N28: =N27/N20 -> 0.16208306 | O28: =O27/O20 -> 0.16208306 | ... Q28: =Q27/Q20 -> 0.16208306
B30: Total Cost of Sales | H30: =H24+H27 -> 6764.7422 | I30: =I24+I27 -> 7900.8545 | J30: =J24+J27 -> 8302.8639 | K30: =K24+K27 -> 7968.4139 | L30: =L24+L27 -> 8127.7822 | M30: =M24+M27 -> 8290.3379 | N30: =N24+N27 -> 8456.1446 | O30: =O24+O27 -> 8625.2675 | ... Q30: =Q24+Q27 -> 8973.7283
B32: Gross Profit | H32: =H20-H30 -> 6798.7149 | I32: =I20-I30 -> 7854.7041 | J32: =J20-J30 -> 8077.2333 | K32: =K20-K30 -> 9223.553 | L32: =L20-L30 -> 10224.024 | M32: =M20-M30 -> 10428.505 | N32: =N20-N30 -> 10637.075 | O32: =O20-O30 -> 10849.816 | ... Q32: =Q20-Q30 -> 11288.149 | S32: =+(I32/H32)^(1/(COLUMNS(H32:I32)-1))-1 -> 0.15532188 | T32: =+(Q32/J32)^(1/(COLUMNS(J32:Q32)-1))-1 -> 0.048976425
B33: % margin | H33: =H32/H20 -> 0.50125236 | I33: =I32/I20 -> 0.49853543 | J33: =J32/J20 -> 0.49311266 | K33: =K32/K20 -> 0.53650365 | L33: =L32/L20 -> 0.55711268 | M33: =M32/M20 -> 0.55711268 | N33: =N32/N20 -> 0.55711268 | O33: =O32/O20 -> 0.55711268 | ... Q33: =Q32/Q20 -> 0.55711268
B35: Operating Expenses
B36: G&A | H36: ='Original & Adjusted Data'!V24 -> 3732.3638 | I36: ='Original & Adjusted Data'!W24 -> 4224.707 | J36: ='Original & Adjusted Data'!X24 -> 4056.7653 | K36: ='Original & Adjusted Data'!Y24 -> 4200.9513 | L36: ='Original & Adjusted Data'!Z24 -> 4279.3504 | M36: ='Original & Adjusted Data'!AA24 -> 4361.0574 | N36: ='Original & Adjusted Data'!AB24 -> 4443.0985 | O36: ='Original & Adjusted Data'!AC24 -> 4527.5005 | ... Q36: ='Original & Adjusted Data'!AE24 -> 4700.4963 | S36: =+(I36/H36)^(1/(COLUMNS(H36:I36)-1))-1 -> 0.1319119 | T36: =+(Q36/J36)^(1/(COLUMNS(J36:Q36)-1))-1 -> 0.021263216
B37: % of revenue | H37: =H36/H20 -> 0.27517791 | I37: =I36/I20 -> 0.26814073 | J37: =J36/J20 -> 0.2476643 | K37: =K36/K20 -> 0.24435548 | L37: =L36/L20 -> 0.23318415 | M37: =M36/M20 -> 0.23297687 | N37: =N36/N20 -> 0.23270557 | O37: =O36/O20 -> 0.23247656 | ... Q37: =Q36/Q20 -> 0.23198721
B39: Facility/Office Rent | H39: ='Original & Adjusted Data'!V25 -> 233.78641 | I39: ='Original & Adjusted Data'!W25 -> 231.49663 | J39: ='Original & Adjusted Data'!X25 -> 273.1192 | K39: ='Original & Adjusted Data'!Y25 -> 273.1192 | L39: ='Original & Adjusted Data'!Z25 -> 277.21599 | M39: ='Original & Adjusted Data'!AA25 -> 281.37423 | N39: ='Original & Adjusted Data'!AB25 -> 285.59484 | O39: ='Original & Adjusted Data'!AC25 -> 289.87876 | ... Q39: ='Original & Adjusted Data'!AE25 -> 298.64035 | S39: =+(I39/H39)^(1/(COLUMNS(H39:I39)-1))-1 -> -0.0097943247 | T39: =+(Q39/J39)^(1/(COLUMNS(J39:Q39)-1))-1 -> 0.012843445
B40: % of revenue | H40: =H39/H20 -> 0.017236491 | I40: =I39/I20 -> 0.014693013 | J40: =J39/J20 -> 0.016673845 | K40: =K39/K20 -> 0.015886443 | L40: =L39/L20 -> 0.015105651 | M40: =M39/M20 -> 0.015031604 | N40: =N39/N20 -> 0.01495792 | O40: =O39/O20 -> 0.014884597 | ... Q40: =Q39/Q20 -> 0.014739027
B42: Bad Debt Expense | H42: ='Original & Adjusted Data'!V26 -> 139.57787 | I42: ='Original & Adjusted Data'!W26 -> 21.18842 | J42: ='Original & Adjusted Data'!X26 -> 110.17088 | K42: ='Original & Adjusted Data'!Y26 -> 110.17056 | L42: ='Original & Adjusted Data'!Z26 -> 111.82312 | M42: ='Original & Adjusted Data'!AA26 -> 113.50047 | N42: ='Original & Adjusted Data'!AB26 -> 115.20297 | O42: ='Original & Adjusted Data'!AC26 -> 116.93102 | ... Q42: ='Original & Adjusted Data'!AE26 -> 120.46526 | S42: =+(I42/H42)^(1/(COLUMNS(H42:I42)-1))-1 -> -0.84819642 | T42: =+(Q42/J42)^(1/(COLUMNS(J42:Q42)-1))-1 -> 0.012843025
B43: % of revenue | H43: =H42/H20 -> 0.01029073 | I43: =I42/I20 -> 0.0013448219 | J43: =J42/J20 -> 0.006725899 | K43: =K42/K20 -> 0.006408258 | L43: =L42/L20 -> 0.0060933031 | M43: =M42/M20 -> 0.006063434 | N43: =N42/N20 -> 0.0060337113 | O43: =O42/O20 -> 0.0060041343 | ... Q43: =Q42/Q20 -> 0.0059454145
B45: Other | H45: ='Original & Adjusted Data'!V27 -> 202.16042 | I45: ='Original & Adjusted Data'!W27 -> 291.00544 | J45: ='Original & Adjusted Data'!X27 -> 320.60966 | K45: ='Original & Adjusted Data'!Y27 -> 176.81 | L45: ='Original & Adjusted Data'!Z27 -> 179.46215 | M45: ='Original & Adjusted Data'!AA27 -> 182.15408 | N45: ='Original & Adjusted Data'!AB27 -> 184.88639 | O45: ='Original & Adjusted Data'!AC27 -> 187.65969 | ... Q45: ='Original & Adjusted Data'!AE27 -> 193.3317 | S45: =+(I45/H45)^(1/(COLUMNS(H45:I45)-1))-1 -> 0.43947785 | T45: =+(Q45/J45)^(1/(COLUMNS(J45:Q45)-1))-1 -> -0.06971061
B46: % of revenue | H46: =H45/H20 -> 0.014904785 | I46: =I45/I20 -> 0.018470017 | J46: =J45/J20 -> 0.019573123 | K46: =K45/K20 -> 0.010284454 | L46: =L45/L20 -> 0.0097789911 | M46: =M45/M20 -> 0.0097310549 | N46: =N45/N20 -> 0.0096833536 | O46: =O45/O20 -> 0.0096358862 | ... Q46: =Q45/Q20 -> 0.0095416483
B48: Total Operating Expenses | H48: =-(H36+H39+H42+H45) -> -4307.8885 | I48: =-(I36+I39+I42+I45) -> -4768.3975 | J48: =-(J36+J39+J42+J45) -> -4760.6651 | K48: =-(K36+K39+K42+K45) -> -4761.0511 | L48: =-(L36+L39+L42+L45) -> -4847.8516 | M48: =-(M36+M39+M42+M45) -> -4938.0861 | N48: =-(N36+N39+N42+N45) -> -5028.7827 | O48: =-(O36+O39+O42+O45) -> -5121.97 | ... Q48: =-(Q36+Q39+Q42+Q45) -> -5312.9336 | S48: =+(I48/H48)^(1/(COLUMNS(H48:I48)-1))-1 -> 0.10689901 | T48: =+(Q48/J48)^(1/(COLUMNS(J48:Q48)-1))-1 -> 0.015803108
B49: % of revenue | H49: =-H48/H20 -> 0.31760991 | I49: =-I48/I20 -> 0.30264858 | J49: =-J48/J20 -> 0.29063717 | K49: =-K48/K20 -> 0.27693464 | L49: =-L48/L20 -> 0.2641621 | M49: =-M48/M20 -> 0.26380297 | N49: =-N48/N20 -> 0.26338056 | O49: =-O48/O20 -> 0.26300118 | ... Q49: =-Q48/Q20 -> 0.2622133
B51: EBIT | H51: =H32+H48 -> 2490.8265 | I51: =I32+I48 -> 3086.3067 | J51: =J32+J48 -> 3316.5682 | K51: =K32+K48 -> 4462.5019 | L51: =L32+L48 -> 5376.1724 | M51: =M32+M48 -> 5490.4184 | N51: =N32+N48 -> 5608.2919 | O51: =O32+O48 -> 5727.8461 | ... Q51: =Q32+Q48 -> 5975.2151 | S51: =+(I51/H51)^(1/(COLUMNS(H51:I51)-1))-1 -> 0.23906931 | T51: =+(Q51/J51)^(1/(COLUMNS(J51:Q51)-1))-1 -> 0.087736032
B52: % margin | H52: =H51/H20 -> 0.18364245 | I52: =I51/I20 -> 0.19588684 | J52: =J51/J20 -> 0.20247549 | K52: =K51/K20 -> 0.25956901 | L52: =L51/L20 -> 0.29295059 | M52: =M51/M20 -> 0.29330972 | N52: =N51/N20 -> 0.29373213 | O52: =O51/O20 -> 0.2941115 | ... Q52: =Q51/Q20 -> 0.29489938
B54: EBITDA | H54: =H51+H68 -> 3033.3648 | I54: =I51+I68 -> 3700.7734 | J54: =J51+J68 -> 3955.392 | K54: =K51+K68 -> 5132.9886 | L54: =L51+L68 -> 6091.8929 | M54: =M51+M68 -> 6220.4532 | N54: =N51+N68 -> 6352.9274 | O54: =O51+O68 -> 6487.3744 | ... Q54: =Q51+Q68 -> 6765.4283 | S54: =+(I54/H54)^(1/(COLUMNS(H54:I54)-1))-1 -> 0.22002255 | T54: =+(Q54/J54)^(1/(COLUMNS(J54:Q54)-1))-1 -> 0.079694335
B55: % margin | H55: =H54/H20 -> 0.22364245 | I55: =I54/I20 -> 0.23488684 | J55: =J54/J20 -> 0.24147549 | K55: =K54/K20 -> 0.29856901 | L55: =L54/L20 -> 0.33195059 | M55: =M54/M20 -> 0.33230972 | N55: =N54/N20 -> 0.33273213 | O55: =O54/O20 -> 0.3331115 | ... Q55: =Q54/Q20 -> 0.33389938
B57: Taxes | H57: =-H51*H58 -> -660.06902 | I57: =-I51*I58 -> -817.87126 | J57: =-J51*J58 -> -878.89058 | K57: =-K51*K58 -> -1182.563 | L57: =-L51*L58 -> -1424.6857 | M57: =-M51*M58 -> -1454.9609 | N57: =-N51*N58 -> -1486.1974 | O57: =-O51*O58 -> -1517.8792 | ... Q57: =-Q51*Q58 -> -1583.432
B58: % tax rate | H58: =$F$11 -> 0.265 | I58: =$F$11 -> 0.265 | J58: =$F$11 -> 0.265 | K58: =$F$11 -> 0.265 | L58: =$F$11 -> 0.265 | M58: =$F$11 -> 0.265 | N58: =$F$11 -> 0.265 | O58: =$F$11 -> 0.265 | ... Q58: =$F$11 -> 0.265
...

Sheet WACC
B2: WACC Calculation
B3: Company ABC/SNS Health
B4: All $ in CAD 000's unless otherwise stated
B6: WACC Calculation | F6: Beta Calculation
F7: Company | H7: Levered Beta | I7: Debt | J7: Equity Value | K7: D/E | L7: Tax Rate | M7: Unlevered Beta | N7: Correlation
B8: Cost of Equity | F8: 1 | G8: =Comps!B8 -> Jamieson Wellness (TSX: JWEL) | H8: =Comps!E8 -> 0.68 | I8: 417.3 | J8: =Comps!F8 -> 1463.67 | K8: =I8/J8 -> 0.28510525 | L8: 0.265 | M8: =H8/(1+(1-L8)*K8) -> 0.56219145 | N8: 0.114
B9: Risk Free Rate (10 Year Treasury Yield) | D9: 0.04469 | F9: 2 | G9: =Comps!B9 -> USANA Health Sciences (NYSE: USNA) | H9: =Comps!E9 -> 0.64 | I9: 23 | J9: =Comps!F9 -> 582.552 | K9: =I9/J9 -> 0.039481454 | L9: 0.265 | M9: =H9/(1+(1-L9)*K9) -> 0.62195167 | N9: 0.469
B10: Equity Risk Premium | D10: 0.0421 | F10: 3 | G10: =Comps!B10 -> Herbalife (NYSE: HLF) | H10: =Comps!E10 -> 0.89 | I10: 2400.6 | J10: =Comps!F10 -> 944.704 | K10: =I10/J10 -> 2.5411134 | L10: 0.265 | M10: =H10/(1+(1-L10)*K10) -> 0.31035126 | N10: 0.277
B11: Levered Beta | D11: =H23 -> 0.63148808 | F11: 4 | G11: =Comps!B11 -> Medifast (NYSE: MED) | H11: =Comps!E11 -> 0.89 | I11: 14.6 | J11: =Comps!F11 -> 141.007 | K11: =I11/J11 -> 0.10354096 | L11: 0.265 | M11: =H11/(1+(1-L11)*K11) -> 0.82705868 | N11: 0.258
B12: Average Correlation | D12: =N23 -> 0.27366667 | F12: 5 | G12: =Comps!B12 -> LifeVantage (Nasdaq: LFVN) | H12: =Comps!E12 -> 0.46 | I12: 12.4 | J12: =Comps!F12 -> 159.768 | K12: =I12/J12 -> 0.077612538 | L12: 0.265 | M12: =H12/(1+(1-L12)*K12) -> 0.43517533 | N12: 0.131
B13: Total Beta | D13: =D11/D12 -> 2.3075082 | F13: 6 | G13: =Comps!B13 -> Nature’s Sunshine (Nasdaq: NATR) | H13: =Comps!E13 -> 1.13 | I13: 14.8 | J13: =Comps!F13 -> 276.575 | K13: =I13/J13 -> 0.053511706 | L13: 0.265 | M13: =H13/(1+(1-L13)*K13) -> 1.0872377 | N13: 0.393
B14: Illiquidity Discount | D14: 0.05 | F14: Min | H14: =MIN(H8:H13) -> 0.46 | I14: =MIN(I8:I13) -> 12.4 | J14: =MIN(J8:J13) -> 141.007 | K14: =MIN(K8:K13) -> 0.039481454 | L14: =MIN(L8:L13) -> 0.265 | M14: =MIN(M8:M13) -> 0.31035126 | N14: =MIN(N8:N13) -> 0.114
B15: Size Premium | D15: 0.03 | F15: 0.25 | H15: =PERCENTILE(H8:H13,0.25) -> 0.65 | I15: =PERCENTILE(I8:I13,0.25) -> 14.65 | J15: =PERCENTILE(J8:J13,0.25) -> 188.96975 | K15: =PERCENTILE(K8:K13,0.25) -> 0.059536914 | L15: =PERCENTILE(L8:L13,0.25) -> 0.265 | M15: =PERCENTILE(M8:M13,0.25) -> 0.46692936 | N15: =PERCENTILE(N8:N13,0.25) -> 0.16275
B16: CAPM/Cost of Equity | D16: =D9+D13*(D10) +D14+D15 -> 0.2218361 | F16: Mean | H16: =AVERAGE(H8:H13) -> 0.78166667 | I16: =AVERAGE(I8:I13) -> 480.45 | J16: =AVERAGE(J8:J13) -> 594.71267 | K16: =AVERAGE(K8:K13) -> 0.51672755 | L16: =AVERAGE(L8:L13) -> 0.265 | M16: =AVERAGE(M8:M13) -> 0.64066102 | N16: =AVERAGE(N8:N13) -> 0.27366667
F17: Median | H17: =MEDIAN(H8:H13) -> 0.785 | I17: =MEDIAN(I8:I13) -> 18.9 | J17: =MEDIAN(J8:J13) -> 429.5635 | K17: =MEDIAN(K8:K13) -> 0.090576749 | L17: =MEDIAN(L8:L13) -> 0.265 | M17: =MEDIAN(M8:M13) -> 0.59207156 | N17: =MEDIAN(N8:N13) -> 0.2675
B18: Cost of Debt | F18: 0.75 | H18: =PERCENTILE(H8:H13,0.75) -> 0.89 | I18: =PERCENTILE(I8:I13,0.75) -> 318.725 | J18: =PERCENTILE(J8:J13,0.75) -> 854.166 | K18: =PERCENTILE(K8:K13,0.75) -> 0.23971418 | L18: =PERCENTILE(L8:L13,0.75) -> 0.265 | M18: =PERCENTILE(M8:M13,0.75) -> 0.77578193 | N18: =PERCENTILE(N8:N13,0.75) -> 0.364
B19: Interest Rate on Debt | D19: 0.07 | F19: Max | H19: =MAX(H8:H13) -> 1.13 | I19: =MAX(I8:I13) -> 2400.6 | J19: =MAX(J8:J13) -> 1463.67 | K19: =MAX(K8:K13) -> 2.5411134 | L19: =MAX(L8:L13) -> 0.265 | M19: =MAX(M8:M13) -> 1.0872377 | N19: =MAX(N8:N13) -> 0.469
B20: Tax Rate | D20: =L23 -> 0.265
B21: Cost of Debt Post-Tax | D21: =D19*(1-D20) -> 0.05145 | F21: Relevered Beta
F22: Company | H22: Levered Beta | I22: Debt Units | J22: Equity Values Units | K22: Optimal D/E | L22: Tax Rate | M22: Unlevered Beta | N22: Correlation
B23: Total Equity | D23: ='DCF Model - Base (1)'!C12 -> 10500 | F23: ABC Corp. | H23: =M23*(1+(1-L23)*K23) -> 0.63148808 | I23: =D23+D24-J23 -> 996.64786 | J23: =(D23+D24)/(1+K23) -> 11003.352 | K23: =K17 -> 0.090576749 | L23: =L16 -> 0.265 | M23: =M17 -> 0.59207156 | N23: =N16 -> 0.27366667
B24: Total Debt | D24: ='DCF Model - Base (1)'!F16 -> 1500
B26: Current Debt/Equity Ratio | D26: =D28/D27 -> 0.14285714
B27: Current Equity/Capital | D27: =D23/(D23+D24) -> 0.875
B28: Current Debt/Capital | D28: =D24/(D23+D24) -> 0.125
B30: Optimal Debt/Equity Ratio | D30: =D32/D31 -> 0.090576749
B31: Optimal Equity/Capital | D31: =J23/(I23+J23) -> 0.91694601
B32: Optimal Debt/Capital | D32: =I23/(I23+J23) -> 0.083053988
A34: x | B34: WACC | D34: =(D31*D16) + (D32*D21) -> 0.20768485

Sheet Comps
A2: x | B2: Comparable Companies Analysis
B3: Company ABC/SNS Health
B4: All $ in CAD 000's unless otherwise stated
C6: Share | D6: Shares | E6: Levered | F6: Market | G6: Enterprise | H6: EBITDA Margin | I6: EV/EBITDA | K6: EV/Sales | M6: Debt/Equity | P6: EBITDA | R6: Sales
B7: Company | C7: Price | D7: Outstanding | E7: Beta | F7: Cap | G7: Value | H7: LTM | I7: LTM | J7: NTM | K7: LTM | M7: Ratio | O7: Ticker | P7: LTM | Q7: NTM | R7: LTM | S7: NTM
B8: Jamieson Wellness (TSX: JWEL) | C8: 35.1 | D8: 41.7 | E8: 0.68 | F8: =+D8*C8 -> 1463.67 | G8: 1868 | H8: =P8/R8 -> 0.1472662 | I8: =+$G8/P8 -> 16.874435 | J8: =+$G8/Q8 -> 10.408425 | K8: =+$G8/R8 -> 2.4850339 | L8: =+$G8/S8 -> 2.081685 | M8: 0.79 | O8: JWEL | P8: 110.7 | Q8: 179.47 | R8: 751.7 | S8: 897.35
B9: USANA Health Sciences (NYSE: USNA) | C9: 31.32 | D9: 18.6 | E9: 0.64 | F9: =+D9*C9 -> 582.552 | G9: 480.8 | H9: =P9/R9 -> 0.08787948 | I9: =+$G9/P9 -> 6.2441558 | J9: =+$G9/Q9 -> 3.2643085 | K9: =+$G9/R9 -> 0.54873317 | L9: =+$G9/S9 -> 0.46679612 | M9: 0.039 | O9: USNA | P9: 77 | Q9: 147.29 | R9: 876.2 | S9: 1030
B10: Herbalife (NYSE: HLF) | C10: 9.28 | D10: 101.8 | E10: 0.89 | F10: =+D10*C10 -> 944.704 | G10: 3016.3 | H10: =P10/R10 -> 0.12580547 | I10: =+$G10/P10 -> 4.8431278 | J10: =+$G10/Q10 -> 4.4532865 | K10: =+$G10/R10 -> 0.60929199 | L10: =+$G10/S10 -> 0.58540969 | M10: N/A | O10: HLF | P10: 622.8 | Q10: 677.32 | R10: 4950.5 | S10: 5152.46
B11: Medifast (NYSE: MED) | C11: 13.69 | D11: 10.3 | E11: 0.89 | F11: =+D11*C11 -> 141.007 | G11: -8.4 | H11: =P11/R11 -> 0.034774609 | I11: =+$G11/P11 -> -0.44444444 | J11: =+$G11/Q11 -> 0.91304348 | K11: =+$G11/R11 -> -0.015455382 | L11: =+$G11/S11 -> -0.022352315 | M11: 0.069 | O11: MED | P11: 18.9 | Q11: -9.2 | R11: 543.5 | S11: 375.8
B12: LifeVantage (Nasdaq: LFVN) | C12: 12.68 | D12: 12.6 | E12: 0.46 | F12: =+D12*C12 -> 159.768 | G12: 149.5 | H12: =P12/R12 -> 0.072874494 | I12: =+$G12/P12 -> 9.2283951 | J12: =+$G12/Q12 -> 6.177686 | K12: =+$G12/R12 -> 0.67251462 | L12: =+$G12/S12 -> 0.60313874 | M12: 0.363 | O12: LFVN | P12: 16.2 | Q12: 24.2 | R12: 222.3 | S12: 247.87
B13: Nature’s Sunshine (Nasdaq: NATR) | C13: 14.95 | D13: 18.5 | E13: 1.13 | F13: =+D13*C13 -> 276.575 | G13: 210.2 | H13: =P13/R13 -> 0.079281647 | I13: =+$G13/P13 -> 5.8066298 | J13: =+$G13/Q13 -> 4.4962567 | K13: =+$G13/R13 -> 0.46035918 | L13: =+$G13/S13 -> 0.44704381 | M13: 0.089 | O13: NATR | P13: 36.2 | Q13: 46.75 | R13: 456.6 | S13: 470.2
B15: Minimum | F15: =MIN(F8:F13) -> 141.007 | G15: =MIN(G8:G13) -> -8.4 | H15: =MIN(H8:H13) -> 0.034774609 | I15: =MIN(I8:I13) -> -0.44444444 | J15: =MIN(J8:J13) -> 0.91304348 | K15: =MIN(K8:K13) -> -0.015455382 | L15: =MIN(L8:L13) -> -0.022352315 | M15: =MIN(M8:M13) -> 0.039
B16: 0.25 | F16: =PERCENTILE(F8:F13,0.25) -> 188.96975 | G16: =PERCENTILE(G8:G13,0.25) -> 164.675 | H16: =PERCENTILE(H8:H13,0.25) -> 0.074476282 | I16: =PERCENTILE(I8:I13,0.25) -> 5.0840033 | J16: =PERCENTILE(J8:J13,0.25) -> 3.561553 | K16: =PERCENTILE(K8:K13,0.25) -> 0.48245267 | L16: =PERCENTILE(L8:L13,0.25) -> 0.45198189 | M16: =PERCENTILE(M8:M13,0.25) -> 0.069
B17: Average | F17: =AVERAGE(F8:F13) -> 594.71267 | G17: =AVERAGE(G8:G13) -> 952.73333 | H17: =AVERAGE(H8:H13) -> 0.09131365 | I17: =AVERAGE(I8:I13) -> 7.0920499 | J17: =AVERAGE(J8:J13) -> 4.9521677 | K17: =AVERAGE(K8:K13) -> 0.79341292 | L17: =AVERAGE(L8:L13) -> 0.69362017 | M17: =AVERAGE(M8:M13) -> 0.27
B18: Median | F18: =MEDIAN(F8:F13) -> 429.5635 | G18: =MEDIAN(G8:G13) -> 345.5 | H18: =MEDIAN(H8:H13) -> 0.083580563 | I18: =MEDIAN(I8:I13) -> 6.0253928 | J18: =MEDIAN(J8:J13) -> 4.4747716 | K18: =MEDIAN(K8:K13) -> 0.57901258 | L18: =MEDIAN(L8:L13) -> 0.5261029 | M18: =MEDIAN(M8:M13) -> 0.089
B19: 0.75 | F19: =PERCENTILE(F8:F13,0.75) -> 854.166 | G19: =PERCENTILE(G8:G13,0.75) -> 1521.2 | H19: =PERCENTILE(H8:H13,0.75) -> 0.11632398 | I19: =PERCENTILE(I8:I13,0.75) -> 8.4823353 | J19: =PERCENTILE(J8:J13,0.75) -> 5.7573286 | K19: =PERCENTILE(K8:K13,0.75) -> 0.65670896 | L19: =PERCENTILE(L8:L13,0.75) -> 0.59870648 | M19: =PERCENTILE(M8:M13,0.75) -> 0.363
A20: x | B20: Max | F20: =MAX(F8:F13) -> 1463.67 | G20: =MAX(G8:G13) -> 3016.3 | H20: =MAX(H8:H13) -> 0.1472662 | I20: =MAX(I8:I13) -> 16.874435 | J20: =MAX(J8:J13) -> 10.408425 | K20: =MAX(K8:K13) -> 2.4850339 | L20: =MAX(L8:L13) -> 2.081685 | M20: =MAX(M8:M13) -> 0.79

Sheet Assumption Breakdown
C2: Depreciation Assumptions
C3: Company ABC/SNS Health
C4: All $ in CAD 000's unless otherwise stated
C6: Average D&A as % of Reenue | D6: =AVERAGE(F10:F15) -> 0.020777064
D8: LTM | F8: % of
C9: Company | D9: Revenue | E9: D&A | F9: Revenue
C10: Jamieson Wellness (TSX: JWEL) | D10: 733780 | E10: 12588 | F10: =E10/D10 -> 0.017155006
C11: USANA Health Sciences (NYSE: USNA) | D11: 854503 | E11: 11038 | F11: =E11/D11 -> 0.01291745
C12: Herbalife (NYSE: HLF) | D12: 4993100 | E12: 121400 | F12: =E12/D12 -> 0.024313553
C13: Medifast (NYSE: MED) | D13: 602463 | E13: 12707 | F13: =E13/D13 -> 0.021091752
C14: LifeVantage (Nasdaq: LFVN) | D14: 200164 | E14: 3581 | F14: =E14/D14 -> 0.01789033
C15: Nature’s Sunshine (Nasdaq: NATR) | D15: 454364 | E15: 14219 | F15: =E15/D15 -> 0.031294293

Sheet Data ->

Sheet Data Given (Recalculated)
B1: ABC
B2: Preliminary Base Case
G3: Actual | I3: Projections
B4: Period Start | E4: 43101 | F4: 42736 | G4: 44197 | H4: 44562 | I4: 44927 | J4: 45292 | K4: 45658 | L4: 46023 | M4: 46388 | N4: 46753 | O4: 47119 | P4: 47484
B5: Period End | C5: Unit | E5: 42735 | F5: 43100 | G5: 44561 | H5: 44926 | I5: 45291 | J5: 45657 | K5: 46022 | L5: 46387 | M5: 46752 | N5: 47118 | O5: 47483 | P5: 47848
B6: Fiscal Year | E6: =YEAR(E5) -> 2016 | F6: =YEAR(F5) -> 2017 | G6: =YEAR(G5) -> 2021 | H6: =YEAR(H5) -> 2022 | I6: =YEAR(I5) -> 2023 | J6: =YEAR(J5) -> 2024 | K6: =YEAR(K5) -> 2025 | L6: =YEAR(L5) -> 2026 | ... P6: =YEAR(P5) -> 2030
B7: Days in Period | E7: =+E5-E4+1 -> -365 | F7: =+F5-F4+1 -> 365 | G7: =+G5-G4+1 -> 365 | H7: =+H5-H4+1 -> 365 | I7: =+I5-I4+1 -> 365 | J7: =+J5-J4+1 -> 366 | K7: =+K5-K4+1 -> 365 | L7: =+L5-L4+1 -> 365 | ... P7: =+P5-P4+1 -> 365
B8: Days in Year | E8: =+E7 -> -365 | F8: =+F7 -> 365 | G8: =+G7 -> 365 | H8: =+H7 -> 365 | I8: =+I7 -> 365 | J8: =+J7 -> 366 | K8: =+K7 -> 365 | L8: =+L7 -> 365 | ... P8: =+P7 -> 365
A10: Financial Summary
B12: Revenue | C12: [$] | E12: 0 | F12: 0 | G12: 13563.457 | H12: 15755.559 | I12: 16380.097 | J12: 17191.967 | K12: 18351.806 | L12: 18718.842 | M12: 19093.219 | N12: 19475.084 | O12: 19864.585 | P12: 20261.877
B13: Growth | C13: [%] | H13: =H12/G12-1 -> 0.16161819 | I13: =I12/H12-1 -> 0.039639257 | J13: =J12/I12-1 -> 0.049564399 | K13: =K12/J12-1 -> 0.067464028 | L13: =L12/K12-1 -> 0.02 | M13: =M12/L12-1 -> 0.02 | N13: =N12/M12-1 -> 0.02 | O13: =O12/N12-1 -> 0.02 | P13: =P12/O12-1 -> 0.02
B15: Cost of Sales
B16: Purchases | C16: [$] | E16: 0 | F16: 0 | G16: 4886.8441 | H16: 5278.8393 | I16: 5386.671 | J16: 5052.221 | K16: 5153.2654 | L16: 5256.3307 | M16: 5361.4573 | N16: 5468.6864 | O16: 5578.0602 | P16: 5689.6214
B17: Sales Commission | C17: [$] | E17: 0 | F17: 0 | G17: 1877.8981 | H17: 2622.0151 | I17: 2916.193 | J17: 2916.193 | K17: 2974.5168 | L17: 3034.0072 | M17: 3094.6873 | N17: 3156.5811 | O17: 3219.7127 | P17: 3284.1069
B18: Total Cost of Sales | E18: =+SUM(E16:E17) -> 0 | F18: =+SUM(F16:F17) -> 0 | G18: =SUM(G16:G17) -> 6764.7422 | H18: =SUM(H16:H17) -> 7900.8545 | I18: =SUM(I16:I17) -> 8302.8639 | J18: =SUM(J16:J17) -> 7968.4139 | K18: =SUM(K16:K17) -> 8127.7822 | L18: =SUM(L16:L17) -> 8290.3379 | M18: =SUM(M16:M17) -> 8456.1446 | N18: =SUM(N16:N17) -> 8625.2675 | ... P18: =SUM(P16:P17) -> 8973.7283
B20: Gross Profit | C20: [$] | E20: =+E12-E18 -> 0 | F20: =+F12-F18 -> 0 | G20: =G12-G18 -> 6798.7149 | H20: =H12-H18 -> 7854.7041 | I20: =I12-I18 -> 8077.2333 | J20: =J12-J18 -> 9223.553 | K20: =K12-K18 -> 10224.024 | L20: =L12-L18 -> 10428.505 | M20: =M12-M18 -> 10637.075 | N20: =N12-N18 -> 10849.816 | ... P20: =P12-P18 -> 11288.149
B21: Margin | C21: [%] | E21: =+IFERROR(E20/E$12,"n.a.") -> n.a. | F21: =+IFERROR(F20/F$12,"n.a.") -> n.a. | G21: =G20/G12 -> 0.50125236 | H21: =H20/H12 -> 0.49853543 | I21: =I20/I12 -> 0.49311266 | J21: =J20/J12 -> 0.53650365 | K21: =K20/K12 -> 0.55711268 | L21: =L20/L12 -> 0.55711268 | M21: =M20/M12 -> 0.55711268 | N21: =N20/N12 -> 0.55711268 | ... P21: =P20/P12 -> 0.55711268
B23: Operating Expenses
B24: G & A | C24: [$] | E24: 0 | F24: 0 | G24: =699+G43 -> 3732.3638 | H24: =794+H43 -> 4224.707 | I24: =787+I43 -> 4056.7653 | J24: =931+J43 -> 4200.9513 | K24: =944+K43 -> 4279.3504 | L24: =959+L43 -> 4361.0574 | M24: =973+M43 -> 4443.0985 | N24: =988+N43 -> 4527.5005 | O24: =1003+O43 -> 4613.2905 | P24: =1018+P43 -> 4700.4963
B25: Facility/Office Rent | C25: [$] | E25: 0 | F25: 0 | G25: 233.78641 | H25: 231.49663 | I25: 273.1192 | J25: 273.1192 | K25: 277.21599 | L25: 281.37423 | M25: 285.59484 | N25: 289.87876 | O25: 294.22695 | P25: 298.64035
B26: Bad Debt Expense | C26: [$] | E26: 0 | F26: 0 | G26: 139.57787 | H26: 21.18842 | I26: 110.17088 | J26: 110.17056 | K26: 111.82312 | L26: 113.50047 | M26: 115.20297 | N26: 116.93102 | O26: 118.68498 | P26: 120.46526
B27: Other | C27: [$] | E27: 0 | F27: 0 | G27: 202.16042 | H27: 291.00544 | I27: 320.60966 | J27: 176.81 | K27: 179.46215 | L27: 182.15408 | M27: 184.88639 | N27: 187.65969 | O27: 190.47458 | P27: 193.3317
B28: Total Operating Expenses | C28: [$] | E28: =+SUM(E24:E27) -> 0 | F28: =+SUM(F24:F27) -> 0 | G28: =SUM(G24:G27) -> 4307.8885 | H28: =SUM(H24:H27) -> 4768.3975 | I28: =SUM(I24:I27) -> 4760.6651 | J28: =SUM(J24:J27) -> 4761.0511 | K28: =SUM(K24:K27) -> 4847.8516 | L28: =SUM(L24:L27) -> 4938.0861 | M28: =SUM(M24:M27) -> 5028.7827 | N28: =SUM(N24:N27) -> 5121.97 | ... P28: =SUM(P24:P27) -> 5312.9336
B30: EBITDA (Contribution) | C30: [$] | E30: =+E20-E28 -> 0 | F30: =+F20-F28 -> 0 | G30: =G20-G28 -> 2490.8265 | H30: =H20-H28 -> 3086.3067 | I30: =I20-I28 -> 3316.5682 | J30: =J20-J28 -> 4462.5019 | K30: =K20-K28 -> 5376.1724 | L30: =L20-L28 -> 5490.4184 | M30: =M20-M28 -> 5608.2919 | N30: =N20-N28 -> 5727.8461 | ... P30: =P20-P28 -> 5975.2151 | R30: should be EBIT
B31: Margin | C31: [%] | E31: =+IFERROR(E30/E$12,"n.a.") -> n.a. | F31: =+IFERROR(F30/F$12,"n.a.") -> n.a. | G31: 0.18364245 | H31: 0.19588684 | I31: =I30/I12 -> 0.20247549 | J31: =J30/J12 -> 0.25956901 | K31: =K30/K12 -> 0.29295059 | L31: =L30/L12 -> 0.29330972 | M31: =M30/M12 -> 0.29373213 | N31: =N30/N12 -> 0.2941115 | O31: =O30/O12 -> 0.29450076 | P31: =P30/P12 -> 0.29489938
B34: PURCHASE PRICE (CDN$) | C34: 12000
B35: Working Capital | C35: Additional $100k per year
B36: CAPEX | C36: Additional $1mm per year
B37: Acquisition costs | C37: 250
B38: Exit Value | C38: 6.5X EBITDA
B39: Debt Assumed | C39: 1500
B40: Strucure | C40: 100% share purchase
B41: Sellers | C41: John and Helen Smith
B43: Salaries & Benefits | C43: [$] | E43: 0 | F43: 0 | G43: 3033.3638 | H43: 3430.707 | I43: 3269.7653 | J43: 3269.9513 | K43: 3335.3504 | L43: 3402.0574 | M43: 3470.0985 | N43: 3539.5005 | O43: 3610.2905 | P43: 3682.4963

Sheet Original & Adjusted Data
B1: ABC | S1: ABC
B2: Preliminary Base Case | S2: 0
G3: Actual | I3: Projections | V3: Actual | X3: Projections
B4: Period Start | E4: 43101 | F4: 42736 | G4: 44197 | H4: 44562 | I4: 44927 | J4: 45292 | K4: 45658 | L4: 46023 | M4: 46388 | N4: 46753 | O4: 47119 | P4: 47484 | S4: Period Start | V4: 44197 | W4: 44562 | X4: 44927 | Y4: 45292 | Z4: 45658 | AA4: 46023 | AB4: 46388 | AC4: 46753 | AD4: 47119 | AE4: 47484
B5: Period End | C5: Unit | E5: 42735 | F5: 43100 | G5: 44561 | H5: 44926 | I5: 45291 | J5: 45657 | K5: 46022 | L5: 46387 | M5: 46752 | N5: 47118 | O5: 47483 | P5: 47848 | S5: Period End | T5: Unit | V5: 44561 | W5: 44926 | X5: 45291 | Y5: 45657 | Z5: 46022 | AA5: 46387 | AB5: 46752 | AC5: 47118 | AD5: 47483 | AE5: 47848
B6: Fiscal Year | E6: =YEAR(E5) -> 2016 | F6: =YEAR(F5) -> 2017 | G6: =YEAR(G5) -> 2021 | H6: =YEAR(H5) -> 2022 | I6: =YEAR(I5) -> 2023 | J6: =YEAR(J5) -> 2024 | K6: =YEAR(K5) -> 2025 | L6: =YEAR(L5) -> 2026 | ... P6: =YEAR(P5) -> 2030 | S6: Fiscal Year | V6: =YEAR(V5) -> 2021 | W6: =YEAR(W5) -> 2022 | X6: =YEAR(X5) -> 2023 | Y6: =YEAR(Y5) -> 2024 | Z6: =YEAR(Z5) -> 2025 | AA6: =YEAR(AA5) -> 2026 | AB6: =YEAR(AB5) -> 2027 | AC6: =YEAR(AC5) -> 2028 | ... AE6: =YEAR(AE5) -> 2030
B7: Days in Period | E7: =+E5-E4+1 -> -365 | F7: =+F5-F4+1 -> 365 | G7: =+G5-G4+1 -> 365 | H7: =+H5-H4+1 -> 365 | I7: =+I5-I4+1 -> 365 | J7: =+J5-J4+1 -> 366 | K7: =+K5-K4+1 -> 365 | L7: =+L5-L4+1 -> 365 | ... P7: =+P5-P4+1 -> 365 | S7: Days in Period | V7: =+V5-V4+1 -> 365 | W7: =+W5-W4+1 -> 365 | X7: =+X5-X4+1 -> 365 | Y7: =+Y5-Y4+1 -> 366 | Z7: =+Z5-Z4+1 -> 365 | AA7: =+AA5-AA4+1 -> 365 | AB7: =+AB5-AB4+1 -> 365 | AC7: =+AC5-AC4+1 -> 366 | ... AE7: =+AE5-AE4+1 -> 365
B8: Days in Year | E8: =+E7 -> -365 | F8: =+F7 -> 365 | G8: =+G7 -> 365 | H8: =+H7 -> 365 | I8: =+I7 -> 365 | J8: =+J7 -> 366 | K8: =+K7 -> 365 | L8: =+L7 -> 365 | ... P8: =+P7 -> 365 | S8: Days in Year | V8: =+V7 -> 365 | W8: =+W7 -> 365 | X8: =+X7 -> 365 | Y8: =+Y7 -> 366 | Z8: =+Z7 -> 365 | AA8: =+AA7 -> 365 | AB8: =+AB7 -> 365 | AC8: =+AC7 -> 366 | ... AE8: =+AE7 -> 365
A10: Financial Summary | R10: Financial Summary
B12: Revenue | C12: [$] | E12: 0 | F12: 0 | G12: 13563.457 | H12: 15755.559 | I12: 16380.097 | J12: 17191.967 | K12: 18351.806 | L12: 18718.842 | M12: 19093.219 | N12: 19475.084 | O12: 19864.585 | P12: 20261.877 | S12: Revenue | T12: [$] | V12: 13563.457 | W12: 15755.559 | X12: 16380.097 | Y12: 17191.967 | Z12: 18351.806 | AA12: 18718.842 | AB12: 19093.219 | AC12: 19475.084 | AD12: 19864.585 | AE12: 20261.877
